Workbook

Sheet etap 4
A2: Tabela parametrów i wskaźników inwestycji
A3: parametr | C3: opis | D3: APK | E3: WPK | F3: projekt budowlany | G3: projekt wykonawczy (sprzedaż) | H3: 4
A4: powierzchnia działki | B4: im | C4: Pd | F4: 15390
A5: współczynnik powierzchni zabudowy | F5: =(682+788+810)/F4 -> 0.14814815
A6: powierzchnia utwardzona (w tym) | F6: =F7+F8 -> 4711.5
A7: powierzchnia chodników | F7: 871.7
A8: powierzchnia dróg | F8: 3839.8
A9: powierzchnia biologicznie czynna (w tym) | F9: =F10+F11+F12 -> 6844
A10: powierzchnia biologicznie czynna 100% | F10: 3834
A11: powierzchnia biologicznie czynna na płycie garażu | F11: 1210
A12: dachy i tarasy zielone | F12: 1800
A13: wskaźnik pow. biologicznie czynnej | F13: =(F10+0.5*(F11+F12))/F4 -> 0.34691358
A14: suma powierzchni użytkowej mieszkań i usług | C14: PUM+PUU | D14: =D17+D20 -> 0 | F14: =F17+F20 -> 8682.46
A15: suma lokali mieszkalnych i usługowych | C15: il.m. + il.u. | D15: =D16+D19 -> 0 | F15: =F16+F19 -> 162
A16: ilość lokali mieszkalnych | B16: im | C16: il.m. | F16: 160
A17: powierzchnia użytkowa lokali mieszkalnych | B17: Pum | C17: PUM | F17: 8619.19
A18: średnia wielkość lokalu mieszkalnego | B18: śrm | C18: PUM/il.m. | D18: =IFERROR(D17/D16,"Brak danych") -> Brak danych | F18: =IFERROR(F17/F16,"Brak danych") -> 53.869938
A19: ilość lokali usługowych | B19: iu | C19: il.u. | F19: 2
A20: powierzchnia lokali usługowych | B20: Puu | C20: PUU | F20: 63.27
A21: powierzchnia części wspólnych | B21: imp | F21: 1071.01
A22: powierzchnia części wspólnych (bez powierzchni klatek schodowych, w tym podestów, spoczników, pionowych ciągów komunikacyjnych oraz szybów windowych) | B22: imp | F22: 390.99 | I22: h. garaz | J22: 2539.34
A23: suma miejsc parkingowych zewn. i miejsc postojowych w garażu | C23: impz+impg | D23: =D26+D27 -> 0 | F23: =F26+F27 -> 196
A24: wymagana ilość miejsc parkingowych | F24: 193
A25: ilość miejsc parkingowych zewnętrznych w sprzedaży | B25: imp | F25: 86
A26: ilość miejsc parkingowych zewnętrznych (wszystkich) | B26: imp | C26: impz | F26: 91
A27: ilość miejsc postojowych w garażu | C27: impg | F27: 105
A28: w tym tzw. Miejsca rodzinne (zależne) | F28: 0
A29: powierzchnia miejsc postojowych w garażu | F29: =F27*12.5+5.5 -> 1318
A30: sumaryczna ilość komórek lokatorskich i boksów | C30: ik/b/g+ik | D30: =D31+D36 -> 0 | F30: =F31+F36 -> 89
A31: ilość komórek lokatorskich/boksów w garażu (w tym): | C31: ik/b/g | F31: =F32+F33 -> 89
A32: ilość komórek lokatorskich tradycyjnych | F32: 79
A33: ilość boksów na jednoślady | F33: 10
A34: powierzchnia komórek lokatorskich/boksów w garażu | F34: =173.37+19.97 -> 193.34
A35: powierzchnia wspólna hali garażowej (w tym również pomieszczenia techniczne) | F35: 1770.13
A36: ilość komórek lokatorskich na kondygnacjach naziemnych | C36: ik | F36: 0
A37: ilość klatek schodowych | C37: iks | F37: 3
A38: wysokość budynku | F38: 15,10 i 17,99
A39: wysokość parteru netto | F39: 258
A40: wysokość kondygnacji mieszkalnych netto | F40: 258
A41: Ilość kondygnacji nadziemnych (bez garażu) | F41: 3 i 4
...

Sheet etap 5
A2: Tabela parametrów i wskaźników inwestycji
A3: parametr | C3: opis | D3: APK | E3: WPK | F3: projekt budowlany | G3: projekt wykonawczy (sprzedaż) | H3: 5
A4: powierzchnia działki | B4: im | C4: Pd | F4: 8579
A5: współczynnik powierzchni zabudowy | F5: =(784+882)/F4 -> 0.19419513
A6: powierzchnia utwardzona (w tym) | F6: =F7+F8 -> 2188
A7: powierzchnia chodników | F7: 838
A8: powierzchnia dróg | F8: 1350
A9: powierzchnia biologicznie czynna (w tym) | F9: =F10+F11+F12 -> 6871
A10: powierzchnia biologicznie czynna 100% | F10: 4630
A11: powierzchnia biologicznie czynna na płycie garażu | F11: 900
A12: dachy i tarasy zielone | F12: 1341
A13: wskaźnik pow. biologicznie czynnej | F13: =(F10+0.5*(F11+F12))/F4 -> 0.67029957
A14: suma powierzchni użytkowej mieszkań i usług | C14: PUM+PUU | D14: =D17+D20 -> 0 | F14: =F17+F20 -> 6234.93
A15: suma lokali mieszkalnych i usługowych | C15: il.m. + il.u. | D15: =D16+D19 -> 0 | F15: =F16+F19 -> 114
A16: ilość lokali mieszkalnych | B16: im | C16: il.m. | F16: 114
A17: powierzchnia użytkowa lokali mieszkalnych | B17: Pum | C17: PUM | F17: 6234.93
A18: średnia wielkość lokalu mieszkalnego | B18: śrm | C18: PUM/il.m. | D18: =IFERROR(D17/D16,"Brak danych") -> Brak danych | F18: =IFERROR(F17/F16,"Brak danych") -> 54.692368
A19: ilość lokali usługowych | B19: iu | C19: il.u. | F19: 0
A20: powierzchnia lokali usługowych | B20: Puu | C20: PUU | F20: 0
A21: powierzchnia części wspólnych | B21: imp | F21: 744.46
A22: powierzchnia części wspólnych (bez powierzchni klatek schodowych, w tym podestów, spoczników, pionowych ciągów komunikacyjnych oraz szybów windowych) | B22: imp | F22: 254.78 | I22: h. garaz | J22: 2311.21
A23: suma miejsc parkingowych zewn. i miejsc postojowych w garażu | C23: impz+impg | D23: =D26+D27 -> 0 | F23: =F26+F27 -> 137
A24: wymagana ilość miejsc parkingowych | F24: 137
A25: ilość miejsc parkingowych zewnętrznych w sprzedaży | B25: imp | F25: 40
A26: ilość miejsc parkingowych zewnętrznych (wszystkich) | B26: imp | C26: impz | F26: 43
A27: ilość miejsc postojowych w garażu | C27: impg | F27: 94
A28: w tym tzw. Miejsca rodzinne (zależne) | F28: 0
A29: powierzchnia miejsc postojowych w garażu | F29: =F27*12.5+5.5 -> 1180.5
A30: sumaryczna ilość komórek lokatorskich i boksów | C30: ik/b/g+ik | D30: =D31+D36 -> 0 | F30: =F31+F36 -> 28
A31: ilość komórek lokatorskich/boksów w garażu (w tym): | C31: ik/b/g | F31: =F32+F33 -> 28
A32: ilość komórek lokatorskich tradycyjnych | F32: 21
A33: ilość boksów na jednoślady | F33: 7
A34: powierzchnia komórek lokatorskich/boksów w garażu | F34: 60.78
A35: powierzchnia wspólna hali garażowej (w tym również pomieszczenia techniczne) | F35: 1417.34
A36: ilość komórek lokatorskich na kondygnacjach naziemnych | C36: ik | F36: 0
A37: ilość klatek schodowych | C37: iks | F37: 2
A38: wysokość budynku | F38: 15,10 i 17,99
A39: wysokość parteru netto | F39: 258
A40: wysokość kondygnacji mieszkalnych netto | F40: 258
A41: Ilość kondygnacji nadziemnych (bez garażu) | F41: 3 i 4
...

Sheet etap 6
A2: Tabela parametrów i wskaźników inwestycji
A3: parametr | C3: opis | D3: APK | E3: WPK | F3: projekt budowlany | G3: projekt wykonawczy (sprzedaż) | H3: 6
A4: powierzchnia działki | B4: im | C4: Pd | F4: 12437
A5: współczynnik powierzchni zabudowy | F5: =(682+788+916)/F4 -> 0.19184691
A6: powierzchnia utwardzona (w tym) | F6: =F7+F8 -> 3401.4
A7: powierzchnia chodników | F7: 1126
A8: powierzchnia dróg | F8: 2275.4
A9: powierzchnia biologicznie czynna (w tym) | F9: =F10+F11+F12 -> 7880
A10: powierzchnia biologicznie czynna 100% | F10: 5215
A11: powierzchnia biologicznie czynna na płycie garażu | F11: 807
A12: dachy i tarasy zielone | F12: 1858
A13: wskaźnik pow. biologicznie czynnej | F13: =(F10+0.5*(F11+F12))/F4 -> 0.52645332
A14: suma powierzchni użytkowej mieszkań i usług | C14: PUM+PUU | D14: =D17+D20 -> 0 | F14: =F17+F20 -> 9205.47
A15: suma lokali mieszkalnych i usługowych | C15: il.m. + il.u. | D15: =D16+D19 -> 0 | F15: =F16+F19 -> 171
A16: ilość lokali mieszkalnych | B16: im | C16: il.m. | F16: 171
A17: powierzchnia użytkowa lokali mieszkalnych | B17: Pum | C17: PUM | F17: 9205.47
A18: średnia wielkość lokalu mieszkalnego | B18: śrm | C18: PUM/il.m. | D18: =IFERROR(D17/D16,"Brak danych") -> Brak danych | F18: =IFERROR(F17/F16,"Brak danych") -> 53.833158
A19: ilość lokali usługowych | B19: iu | C19: il.u. | F19: 0
A20: powierzchnia lokali usługowych | B20: Puu | C20: PUU | F20: 0
A21: powierzchnia części wspólnych | B21: imp | F21: 1055.77
A22: powierzchnia części wspólnych (bez powierzchni klatek schodowych, w tym podestów, spoczników, pionowych ciągów komunikacyjnych oraz szybów windowych) | B22: imp | F22: 390.99 | I22: h. garaz | J22: 2701
A23: suma miejsc parkingowych zewn. i miejsc postojowych w garażu | C23: impz+impg | D23: =D26+D27 -> 0 | F23: =F26+F27 -> 211
A24: wymagana ilość miejsc parkingowych | F24: 206
A25: ilość miejsc parkingowych zewnętrznych w sprzedaży | B25: imp | F25: 98
A26: ilość miejsc parkingowych zewnętrznych (wszystkich) | B26: imp | C26: impz | F26: 100
A27: ilość miejsc postojowych w garażu | C27: impg | F27: 111
A28: w tym tzw. Miejsca rodzinne (zależne) | F28: 0
A29: powierzchnia miejsc postojowych w garażu | F29: =F27*12.5+5.5 -> 1393
A30: sumaryczna ilość komórek lokatorskich i boksów | C30: ik/b/g+ik | D30: =D31+D36 -> 0 | F30: =F31+F36 -> 90
A31: ilość komórek lokatorskich/boksów w garażu (w tym): | C31: ik/b/g | F31: =F32+F33 -> 90
A32: ilość komórek lokatorskich tradycyjnych | F32: 75
A33: ilość boksów na jednoślady | F33: 15
A34: powierzchnia komórek lokatorskich/boksów w garażu | F34: 218.5
A35: powierzchnia wspólna hali garażowej (w tym również pomieszczenia techniczne) | F35: 1860.16
A36: ilość komórek lokatorskich na kondygnacjach naziemnych | C36: ik | F36: 0
A37: ilość klatek schodowych | C37: iks | F37: 3
A38: wysokość budynku | F38: 15,10 i 17,99
A39: wysokość parteru netto | F39: 258
A40: wysokość kondygnacji mieszkalnych netto | F40: 258
A41: Ilość kondygnacji nadziemnych (bez garażu) | F41: 3 i 4
...

Sheet zest
A4: powierzchnia działki | B4: im
A5: współczynnik powierzchni zabudowy
A6: powierzchnia utwardzona (w tym)
A7: powierzchnia chodników
A8: powierzchnia dróg
A9: powierzchnia biologicznie czynna (w tym)
A10: powierzchnia biologicznie czynna 100%
A11: powierzchnia biologicznie czynna na płycie garażu
A12: dachy i tarasy zielone
A13: wskaźnik pow. biologicznie czynnej
A14: suma powierzchni użytkowej mieszkań i usług
A15: suma lokali mieszkalnych i usługowych
A16: ilość lokali mieszkalnych | B16: im
A17: powierzchnia użytkowa lokali mieszkalnych | B17: Pum
A18: średnia wielkość lokalu mieszkalnego | B18: śrm
A19: ilość lokali usługowych | B19: iu
A20: powierzchnia lokali usługowych | B20: Puu
A21: powierzchnia części wspólnych | B21: imp
A22: powierzchnia części wspólnych (bez powierzchni klatek schodowych, w tym podestów, spoczników, pionowych ciągów komunikacyjnych oraz szybów windowych) | B22: imp
A23: suma miejsc parkingowych zewn. i miejsc postojowych w garażu
A24: wymagana ilość miejsc parkingowych
A25: ilość miejsc parkingowych zewnętrznych w sprzedaży | B25: imp
A26: ilość miejsc parkingowych zewnętrznych (wszystkich) | B26: imp
A27: ilość miejsc postojowych w garażu
A28: w tym tzw. Miejsca rodzinne (zależne)
A29: powierzchnia miejsc postojowych w garażu
A30: sumaryczna ilość komórek lokatorskich i boksów
A31: ilość komórek lokatorskich/boksów w garażu (w tym):
A32: ilość komórek lokatorskich tradycyjnych
A33: ilość boksów na jednoślady
A34: powierzchnia komórek lokatorskich/boksów w garażu
A35: powierzchnia wspólna hali garażowej (w tym również pomieszczenia techniczne)
A36: ilość komórek lokatorskich na kondygnacjach naziemnych
A37: ilość klatek schodowych
A38: wysokość budynku
... A43: Ilość wind
A44: powierzchnia całkowita (bez balkonów i loggi) | C44: ='etap 4'!F44 -> 12794.83 | D44: ='etap 5'!F44 -> 9582.73 | E44: ='etap 6'!F44 -> 13519.9
A45: powierzchnia całkowita balkonów i loggi | C45: ='etap 4'!F45 -> 1144.76 | D45: ='etap 5'!F45 -> 835.96 | E45: ='etap 6'!F45 -> 1222.36
A46: powierzchnia całkowita (z uwzględnieniem balkonów i loggii) | C46: ='etap 4'!F46 -> 13939.59 | D46: ='etap 5'!F46 -> 10418.69 | E46: ='etap 6'!F46 -> 14742.26
A47: powierzchnia całkowita nadziemia (bez balkonów i loggi) | C47: ='etap 4'!F47 -> 9690.2 | D47: ='etap 5'!F47 -> 6979.39 | E47: ='etap 6'!F47 -> 10261.24
...
